Workbook

Sheet INSTRUCTIONS
B15: Client details
B16: Name
B17: Tax File Number
B18: Date of Birth
B19: Phone number
B20: Email Address
B21: HECS Debt (Y/N)
B22: Private Health Insurance (Y/N)
B23: Rental Property (Y/N)

Sheet D1 Car Expenses
A1: 2018 Tax Deduction Checklist
A4: D1: Car expenses | B4: Kms travelled | C4: Kms @ 0.66 cents
A5: 1.1 Compulsory Travel
A6: OSTT/SAP/Active Shooter | C6: =B6*0.66 -> 0
A7: Secondment Special Units | C7: =B7*0.66 -> 0
A8: Taking Charge/Confirmation Kms | C8: =B8*0.66 -> 0
A9: Carry Bullet Proof Vest Home | C9: =B9*0.66 -> 0
A11: 1.2 Travel to Courts
A12: Supreme Courts | C12: =B12*0.66 -> 0
A13: Magistrates Court | C13: =B13*0.66 -> 0
A14: Family/Other Courts | C14: =B14*0.66 -> 0
A16: 1.3 Car and Driver Compliance
A17: Safe Vehicle Inspection | C17: =B17*0.66 -> 0
A18: EBT Training | C18: =B18*0.66 -> 0
A19: Radar Speed Training | C19: =B19*0.66 -> 0
A20: 4WD Training | C20: =B20*0.66 -> 0
A21: Driver Training
A23: 1.4 Other Police Training
A24: Exams at Academy | C24: =B24*0.66 -> 0
A25: Taking Charge/Confirmation | C25: =B25*0.66 -> 0
A26: Management Meetins | C26: =B26*0.66 -> 0
A27: Operation Task Force Meetings | C27: =B27*0.66 -> 0
A28: FIC/DIC Training/Exams | C28: =B28*0.66 -> 0
A29: Detective Training School | C29: =B29*0.66 -> 0
A30: First Aid Courses | C30: =B30*0.66 -> 0
A32: 1.5 Other Police Business
A33: Voluntary Duties - Public Events | C33: =B33*0.66 -> 0
A34: Travel to Non Usual Stations | C34: =B34*0.66 -> 0
A35: Travel to Equipment Stations | C35: =B35*0.66 -> 0
A37: 1.6 New Police Recruits
A38: Traffic Management | C38: =B38*0.66 -> 0
A39: DTW | C39: =B39*0.66 -> 0
A40: Safe Street | C40: =B40*0.66 -> 0
A41: Highway Patrol | C41: =B41*0.66 -> 0
A42: Booze Bus | C42: =B42*0.66 -> 0
A43: Custody training | C43: =B43*0.66 -> 0
A44: 12 Weeks Temp Placement | C44: =B44*0.66 -> 0
A46: 1.7 New PSO Recruits
A47: PSO VPC | C47: =B47*0.66 -> 0
A48: PSO Mentoring | C48: =B48*0.66 -> 0
...

Sheet D2 Travel
A1: D2: Travel
C2: Amount
A3: Freeway Tolls | C3: 0
A4: Carparking Costs | C4: 0
A5: Live in Accomodation Academy | C5: 0
A6: Other Accomodation and Meals | C6: 0
A7: Travel Costs (Local) | C7: 0
A8: Travel Costs (Interstate) | C8: 0
A9: Travel Costs (Overseas) | C9: 0
A10: Taxis | C10: 0
A11: Travel to alternative workplace | C11: 0
A12: Between 2 separate work places | C12: 0
A13: Miscellaneous | C13: 0
A15: Total | C15: =SUM(C3:C13) -> 0

Sheet D3. Uniform
A1: D3: Uniform
D2: Cost
A3: Academy Wear | D3: 0
A4: Alterations & Repairs to clothing | D4: 0
A5: Blue or Khaki shirts with rank | D5: 0
A6: Boots & Socks | D6: 0
A7: camouflage shirts and trousers | D7: 0
A8: Cargo Pants | D8: 0
A9: Compression Top & Bottoms | D9: 0
A10: Corporate Wardrobe | D10: 0
A11: Covert Oversized Clothing | D11: 0
A12: Deployment Clothing | D12: 0
A13: Drycleaning Uniforms | D13: 0
A14: Fire resistant clothing | D14: 0
... A36: Wooden Coat Hangers | D36: 0
A38: Total | D38: =SUM(D3:D36) -> 150

Sheet D4. Education
A1: D4. Self Education
C2: Amount
A3: TAFE Courses/Certificate | C3: 0
A4: Diploma Courses | C4: 0
A5: Degree Courses | C5: 0
A6: Public Speaking Courses | C6: 0
A7: Media Engagement Courses | C7: 0
A8: Forensic Education | C8: 0
A9: Ethnic Understanding Courses | C9: 0
A10: Prosecutors/Legal Training | C10: 0
A11: Airing/ Search & Rescue Training | C11: 0
A12: Books and reference material | C12: 0
A13: Travel Kms for Education | C13: 0
A15: Total | C15: =SUM(C3:C13) -> 0

Sheet D5. Other Expenses
A1: D5. Other expenses
C2: Yearly Cost | D2: Total
A3: 5.1 Association Fees | D3: 0
A5: 5.2 Mobile and Communication | T5: 0.1
A6: Mobile Phone exp | B6: 0.75 | D6: =B6*C6 -> 0 | T6: 0.2
A7: Mobile Outright Purchase | D7: 0 | T7: 0.3
A8: Mobile Covers and Holders | D8: 0 | T8: 0.4
T9: 0.5
A10: 5.3 Home Office | T10: 0.6
A11: Stationery | D11: 0 | T11: 0.7
A12: Rubber Stamps | D12: 0 | T12: 0.75
A13: Ink/Paper/ Printers uner $300 | D13: 0
A14: Desk/Chairs under $300 | D14: 0
A15: Filing cabinets/Drawers under $300 | D15: 0
A17: 5.4 Computers & Technology
A18: Internet Connection/Plan Costs | B18: 0.1 | C18: 0 | D18: =B18*C18 -> 0
A19: Wireless Keyboard/Mouse | D19: 0
A20: External Hard Drives/USBs | D20: 0
A21: iPads & Covers | D21: 0
A22: Tablets | D22: 0
A23: Router/Modems | D23: 0
A24: SD Camera memory cards | D24: 0
A25: Computer cover/Bags | D25: 0
A26: Virus protection | D26: 0
A27: Software < $300 | D27: 0
A28: Voice/Tape recorders | D28: 0
A29: Other electronic devices < $300 | D29: 0
A31: 5.5 Professional Equipment
A32: Torches & Batteries | D32: 0
A33: Battery Changing Devices | D33: 0
A34: Multi-tools/Leathermans | D34: 0
A35: Vest & Leg Pouches | D35: 0
A36: Key & Equipment Holders | D36: 0
A37: Duty Bags/ Sports Bags | D37: 0
A38: Briefcases | D38: 0
A39: Tactical Watches < $300 | D39: 0
A40: Holsters | D40: 0
A41: Hand Grips | D41: 0
A42: Ulitily belts | D42: 0
A43: Gun Cleaning Materials | D43: 0
...

Sheet OTHERS 
A1: Donations / Tax Fees
A3: Charity Name | B3: Amount
A4: Police Legacy | B4: 0
B5: 0
B6: 0
B7: 0
B8: 0
B9: 0
B10: 0
B11: 0
A12: Last Year Tax Agent Fees | B12: 0
A14: Total | B14: =SUM(B4:B12) -> 0

Sheet Depreciation 
B1: For purchases over $300
A3: S No. | B3: Description | C3: No of months owned the asset | D3: Purchase Price | E3: Business Use | F3: Depreciation amount
A4: 1 | C4: 1 | D4: 0 | E4: 0.25 | F4: =(C4*D4*E4*0.33)/12 -> 0 | R4: 1 | S4: 0.25
A5: 2 | R5: 2 | S5: 0.5
A6: 3 | R6: 3 | S6: 0.75
A7: 4 | R7: 4 | S7: 1
A8: 5 | R8: 5
R9: 6
A10: Total | F10: =SUM(F4:F9) -> 0 | R10: 7
R11: 8
R12: 9
R13: 10
R14: 11
R15: 12

Sheet SUMMARY
B2: D1. Car Expenses | C2: ='D1 Car Expenses'!C51 -> 0
B3: D2. Travel | C3: ='D2 Travel'!C15 -> 0
B4: D3. Uniform | C4: ='D3. Uniform'!D38 -> 150
B5: D4. Education | C5: ='D4. Education'!C15 -> 0
B6: D5. Other expenses | C6: ='D5. Other Expenses'!D65 -> 0
B7: Others | C7: ='OTHERS '!B14 -> 0
B8: Depreciation | C8: ='Depreciation '!F10 -> 0
B9: Total Deduction | C9: =SUM(C2:C6) -> 150
